<?xml version="1.0" encoding="utf-8"?>
<!-- This URDF was automatically created by SolidWorks to URDF Exporter! Originally created by Stephen Brawner (brawner@gmail.com) 
     Commit Version: 1.6.0-4-g7f85cfe  Build Version: 1.6.7995.38578
     For more information, please see http://wiki.ros.org/sw_urdf_exporter -->
<robot
  name="arm">
  <link
    name="base_link">
    <inertial>
      <origin
        xyz="-1.4824527317034E-16 -0.000217414035885836 0.0727671471110202"
        rpy="0 0 0" />
      <mass
        value="0.674186463651997" />
      <inertia
        ixx="0.00295010479446613"
        ixy="1.0218470805528E-18"
        ixz="5.9262051396862E-19"
        iyy="0.00296152086429525"
        iyz="-8.26266658254792E-06"
        izz="0.00273320000431985" />
    </inertial>
    <visual>
      <origin
        xyz="0 0 0"
        rpy="0 0 0" />
      <geometry>
        <mesh
          filename="package://arm_pkg/meshes/base_link.STL" />
      </geometry>
      <material
        name="">
        <color
          rgba="0.898039215686275 0.917647058823529 0.929411764705882 1" />
      </material>
    </visual>
    <collision>
      <origin
        xyz="0 0 0"
        rpy="0 0 0" />
      <geometry>
        <mesh
          filename="package://arm_pkg/meshes/base_link.STL" />
      </geometry>
    </collision>
  </link>
  <link
    name="J1">
    <inertial>
      <origin
        xyz="-1.77910606515968E-06 0.005897163049534 0.229998947042773"
        rpy="0 0 0" />
      <mass
        value="0.734504996688149" />
      <inertia
        ixx="0.00202120167773863"
        ixy="-4.89823514529087E-09"
        ixz="-2.11620457667784E-08"
        iyy="0.00221067656193865"
        iyz="2.47295086272012E-06"
        izz="0.00201535115354741" />
    </inertial>
    <visual>
      <origin
        xyz="0 0 0"
        rpy="0 0 0" />
      <geometry>
        <mesh
          filename="package://arm_pkg/meshes/J1.STL" />
      </geometry>
      <material
        name="">
        <color
          rgba="0.898039215686275 0.917647058823529 0.929411764705882 1" />
      </material>
    </visual>
    <collision>
      <origin
        xyz="0 0 0"
        rpy="0 0 0" />
      <geometry>
        <mesh
          filename="package://arm_pkg/meshes/J1.STL" />
      </geometry>
    </collision>
  </link>
  <joint
    name="J1"
    type="revolute">
    <origin
      xyz="0 0 0"
      rpy="0 0 0" />
    <parent
      link="base_link" />
    <child
      link="J1" />
    <axis
      xyz="0 0 -1" />
    <limit
      lower="-3.14"
      upper="3.14"
      effort="100"
      velocity="100" />
  </joint>
  <link
    name="J2">
    <inertial>
      <origin
        xyz="-2.99173788242083E-07 -0.205171878627219 0.214855220700126"
        rpy="0 0 0" />
      <mass
        value="2.44245996641046" />
      <inertia
        ixx="0.0339892696830772"
        ixy="-2.30786695036266E-08"
        ixz="-2.10894197861353E-08"
        iyy="0.0341736363657584"
        iyz="-6.91545213581086E-05"
        izz="0.00711410938396861" />
    </inertial>
    <visual>
      <origin
        xyz="0 0 0"
        rpy="0 0 0" />
      <geometry>
        <mesh
          filename="package://arm_pkg/meshes/J2.STL" />
      </geometry>
      <material
        name="">
        <color
          rgba="0.898039215686275 0.917647058823529 0.929411764705882 1" />
      </material>
    </visual>
    <collision>
      <origin
        xyz="0 0 0"
        rpy="0 0 0" />
      <geometry>
        <mesh
          filename="package://arm_pkg/meshes/J2.STL" />
      </geometry>
    </collision>
  </link>
  <joint
    name="J2"
    type="revolute">
    <origin
      xyz="0 0.0685 0.245"
      rpy="0 0 0" />
    <parent
      link="J1" />
    <child
      link="J2" />
    <axis
      xyz="0 1 0" />
    <limit
      lower="-3.14"
      upper="3.14"
      effort="100"
      velocity="100" />
  </joint>
  <link
    name="J3">
    <inertial>
      <origin
        xyz="5.01997038722379E-07 0.19122577496937 0.169185336934822"
        rpy="0 0 0" />
      <mass
        value="1.69005326803973" />
      <inertia
        ixx="0.0147262401310724"
        ixy="5.3620328182519E-09"
        ixz="3.23136895343807E-09"
        iyy="0.0148657999989143"
        iyz="2.93849261391728E-05"
        izz="0.00332046741402665" />
    </inertial>
    <visual>
      <origin
        xyz="0 0 0"
        rpy="0 0 0" />
      <geometry>
        <mesh
          filename="package://arm_pkg/meshes/J3.STL" />
      </geometry>
      <material
        name="">
        <color
          rgba="0.898039215686275 0.917647058823529 0.929411764705882 1" />
      </material>
    </visual>
    <collision>
      <origin
        xyz="0 0 0"
        rpy="0 0 0" />
      <geometry>
        <mesh
          filename="package://arm_pkg/meshes/J3.STL" />
      </geometry>
    </collision>
  </link>
  <joint
    name="J3"
    type="revolute">
    <origin
      xyz="0 -0.275 0.56"
      rpy="0 0 0" />
    <parent
      link="J2" />
    <child
      link="J3" />
    <axis
      xyz="0 1 0" />
    <limit
      lower="-3.14"
      upper="3.14"
      effort="100"
      velocity="100" />
  </joint>
  <link
    name="J4">
    <inertial>
      <origin
        xyz="-1.69035502337261E-06 -0.136386631236492 -0.00151245201699624"
        rpy="0 0 0" />
      <mass
        value="0.216727590595791" />
      <inertia
        ixx="0.000251646331581201"
        ixy="1.28295094962965E-09"
        ixz="3.88912040043473E-10"
        iyy="0.000305284443944767"
        iyz="2.23517087012216E-06"
        izz="0.000264255882987725" />
    </inertial>
    <visual>
      <origin
        xyz="0 0 0"
        rpy="0 0 0" />
      <geometry>
        <mesh
          filename="package://arm_pkg/meshes/J4.STL" />
      </geometry>
      <material
        name="">
        <color
          rgba="0.898039215686275 0.917647058823529 0.929411764705882 1" />
      </material>
    </visual>
    <collision>
      <origin
        xyz="0 0 0"
        rpy="0 0 0" />
      <geometry>
        <mesh
          filename="package://arm_pkg/meshes/J4.STL" />
      </geometry>
    </collision>
  </link>
  <joint
    name="J4"
    type="revolute">
    <origin
      xyz="0 0.24825 0.435"
      rpy="0 0 0" />
    <parent
      link="J3" />
    <child
      link="J4" />
    <axis
      xyz="0 -1 0" />
    <limit
      lower="-3.14"
      upper="3.14"
      effort="100"
      velocity="100" />
  </joint>
  <link
    name="J5">
    <inertial>
      <origin
        xyz="1.44682275804881E-08 0.000813612018311136 0.137741340148651"
        rpy="0 0 0" />
      <mass
        value="0.132921242726739" />
      <inertia
        ixx="0.000160532853395347"
        ixy="-2.70545603205785E-10"
        ixz="1.53015366633257E-11"
        iyy="0.000176814275516648"
        iyz="2.08079522567419E-06"
        izz="0.00016684026786328" />
    </inertial>
    <visual>
      <origin
        xyz="0 0 0"
        rpy="0 0 0" />
      <geometry>
        <mesh
          filename="package://arm_pkg/meshes/J5.STL" />
      </geometry>
      <material
        name="">
        <color
          rgba="0.792156862745098 0.819607843137255 0.933333333333333 1" />
      </material>
    </visual>
    <collision>
      <origin
        xyz="0 0 0"
        rpy="0 0 0" />
      <geometry>
        <mesh
          filename="package://arm_pkg/meshes/J5.STL" />
      </geometry>
    </collision>
  </link>
  <joint
    name="J5"
    type="revolute">
    <origin
      xyz="0 -0.16525 -0.04675"
      rpy="0 0 0" />
    <parent
      link="J4" />
    <child
      link="J5" />
    <axis
      xyz="0 0 -1" />
    <limit
      lower="-3.14"
      upper="3.14"
      effort="100"
      velocity="100" />
  </joint>
  <link
    name="J6">
    <inertial>
      <origin
        xyz="-0.00524020386403277 0.106816752865177 -0.789890482662708"
        rpy="0 0 0" />
      <mass
        value="10.4077788545173" />
      <inertia
        ixx="1.51680568443909"
        ixy="0.0039205487008158"
        ixz="-0.0245131180589155"
        iyy="1.47569348728239"
        iyz="0.041066706980443"
        izz="0.0643844943069449" />
    </inertial>
    <visual>
      <origin
        xyz="0 0 0"
        rpy="0 0 0" />
      <geometry>
        <mesh
          filename="package://arm_pkg/meshes/J6.STL" />
      </geometry>
      <material
        name="">
        <color
          rgba="0.792156862745098 0.819607843137255 0.933333333333333 1" />
      </material>
    </visual>
    <collision>
      <origin
        xyz="0 0 0"
        rpy="0 0 0" />
      <geometry>
        <mesh
          filename="package://arm_pkg/meshes/J6.STL" />
      </geometry>
    </collision>
  </link>
  <joint
    name="J6"
    type="revolute">
    <origin
      xyz="0 -0.0491 0.15175"
      rpy="0 0 0" />
    <parent
      link="J5" />
    <child
      link="J6" />
    <axis
      xyz="0 1 0" />
    <limit
      lower="-3.14"
      upper="3.14"
      effort="100"
      velocity="100" />
  </joint>
</robot>